Workbook

Sheet HISTÓRICO 2023-2026
A1: Centro formador | B1: Nombre(s) | C1: Primer apellido | D1: Segundo apellido | E1: RUT | F1: Correo | G1: Carrera | H1: Servicio Clínico HSJD | I1: Tutor Clínico (Profesional) HSJD | J1: Supervisor/Académico Universitario | K1: Nº Rotación | L1: Año Académico | M1: Fecha Inicio Rotación | N1: Fecha Término Rotación | O1: Hora Entrada | P1: Hora Salida | Q1: Asistencia Lunes | R1: Asistencia Martes | S1: Asistencia Miércoles | T1: Asistencia Jueves | U1: Asistencia 3ernes | V1: Fecha Rendición Prueba IAAS | W1: Puntaje Prueba IAAS (8 al 10) | X1: Inmunización Hepatitis B
A2: Universidad Santo Tomás | B2: María | C2: Ajraz | D2: Arriagada | E2: 7208461-6 | F2: maria.ajraz@alumnos.santotomas.cl | G2: Enfermería | H2: Sector C 4º Piso Especialidades Qx | J2: Victoria Herrera | K2: 3ra rotación | L2: 2do año | M2: 45629 | N2: 45645 | O2: 08:00 | P2: 12:00 | V2: 45399 | W2: 9
A3: ENAC | B3: SANDRA ELIZABETH | C3: VALENZUELA | D3: SANTANA | E3: 8519301-5 | F3: sandra.valenzuela@alumnos.enac.cl | G3: Técnico en Enfermería | H3: UGA | I3: Danila Riveros | J3: CLAUDIA ZÚÑIGA AVENDAÑO | K3: 2da rotación | L3: 3er año | M3: 45922 | N3: 45961 | O3: 08:00 | P3: 08:00 | V3: 45908 | W3: 9
A4: ENAC | B4: SANDRA ELIZABETH | C4: VALENZUELA | D4: SANTANA | E4: 8519301-5 | F4: sandra.valenzuela@alumnos.enac.cl | G4: Técnico en Enfermería | H4: UGA | I4: DANIELA RIVERA | J4: CLAUDIA ZÚÑIGA AVENDAÑO | K4: 2da rotación | L4: 3er año | M4: 45922 | N4: 45961 | O4: 08:00 | P4: 08:00 | V4: 45908 | W4: 9
A5: ENAC | B5: SANDRA ELIZABETH | C5: VALENZUELA | D5: SANTANA | E5: 8519301-5 | F5: sandra.valenzuela@alumnos.enac.cl | G5: Técnico en Enfermería | H5: UROLOGÍA | I5: Marjorie Guzmán | J5: CLAUDIA ZÚÑIGA AVENDAÑO | K5: 1ra rotación | L5: 3er año | M5: 45880 | N5: 45919 | V5: 45761 | W5: 9
A6: ENAC | B6: JENNY ELIZABETH | C6: HUERTA | D6: BERRIOS | E6: 9979797-5 | F6: jenny.huerta@alumnos.enac.cl | G6: Técnico en Enfermería | H6: SERVCIO DE AGUDO QUIRÚRGICO VB | I6: MARJORIE GUZMÁN | J6: CLAUDIA ZÚÑIGA AVENDAÑO | K6: 1ra rotación | L6: 3er año | M6: 46097 | N6: 46137 | O6: 08:00 | P6: 08:00 | V6: 46084 | W6: 9
A7: ENAC | B7: JENNY ELIZABETH | C7: HUERTA | D7: BERRIOS | E7: 9979797-5 | F7: jenny.huerta@alumnos.enac.cl | G7: Técnico en Enfermería | H7: SERVCIO DE AGUDO QUIRÚRGICO VB | I7: MARJORIE GUZMÁN | J7: CLAUDIA ZÚÑIGA AVENDAÑO | K7: 1ra rotación | L7: 3er año | M7: 46097 | N7: 46137 | O7: 08:00 | P7: 08:00 | V7: 46084 | W7: 9
A8: ENAC | B8: Andrea Stephanie | C8: Reyes | D8: Calderon | E8: 10975036-0 | F8: anreyesc@alumnos.enac.cl | G8: Técnico en Enfermería | H8: Medicina | J8: Francisco Cortés Bustamante | K8: 2da rotación | L8: 3er año | M8: 45558 | N8: 45598 | O8: 08:00 | P8: 08:00 | V8: 45527 | W8: 10
A9: ENAC | B9: MARIA VICTORIA | C9: ALLENDE | D9: LAGOS | E9: 10982086-5 | F9: maria.allende.l@alumnos.enac.cl | G9: Técnico en Farmacia | H9: FARMACIA HOSPITAL | I9: ELIANA PIZARRO | J9: JORGE VELOZ PEREZ | L9: 3er año | M9: 46097 | N9: 46178 | O9: 08:00 | P9: 17:00 | V9: 46084 | W9: 9
A10: ENAC | B10: PAUL | C10: VÁSQUEZ | D10: VERGARA | E10: 11261728-0 | F10: paul.vasquez@alumnos.enac.cl | G10: Técnico en Enfermería | H10: URGENCIAS | J10: CLAUDIA ZÚÑIGA AVENDAÑO | K10: 2da rotación | L10: 3er año | M10: 45768 | N10: 45808 | O10: 08:00 | P10: 17:30 | V10: 45761 | W10: 9
A11: ENAC | B11: Marlen Antonia | C11: Gacitua | D11: Carrera | E11: 11362371-3 | F11: marlen.gacitua@alumnos.enac.cl | G11: Técnico en Farmacia | H11: Farmacia | I11: Eliana Pizarro | J11: Jasson Espinoza Caicedo | L11: 2do año | M11: 45425 | N11: 45485 | O11: 14:00 | P11: 20:00 | V11: 45419 | W11: 9
A12: ENAC | B12: Marlen Antonia | C12: Gacitua | D12: Carrera | E12: 11362371-3 | F12: marlen.gacitua@alumnos.enac.cl | G12: Técnico en Farmacia | H12: Farmacia | I12: Eliana Pizarro | J12: Jasson Espinoza Caicedo | K12: 1ra rotación | L12: 2do año | M12: 45579 | N12: 45639 | O12: 08:00 | P12: 14:00 | V12: 45568 | W12: 8
A13: Universidad de las Américas | B13: LAURA | C13: GOMEZ | D13: GONZALEZ | E13: 11718075-1 | F13: laura.gomez.gonzalez2@edu.udla.cl | G13: Enfermería | H13: UNAG | I13: MARJORIE GUZMAN | J13: DAVID ESPARZA | K13: 3ra rotación | L13: 5to año | M13: 45838 | N13: 45905 | O13: 08:00 | P13: 08:00 | V13: 45455 | W13: 10
A14: Universidad de las Américas | B14: LAURA | C14: GOMEZ | D14: GONZALEZ | E14: 11718075-1 | F14: Lauraveronica.gomez@mail.com | G14: Enfermería | H14: CIRUGIA 4° PISO SECTOR E | J14: LILY SAN MARTIN BOBADILLA | K14: 3ra rotación | L14: 3er año | M14: 45096 | N14: 45121 | O14: 08:00 | P14: 12:00 | W14: 9
A15: ENAC | B15: LILIAN ISABEL | C15: ARCE | D15: DIAZ | E15: 11976267-7 | F15: lilian.arce@alumnos.enac.cl | G15: Técnico en Odontología | H15: DENTAL | J15: TOMAS IGNACIO MUÑOZ RIPETTI | L15: 2do año | M15: 45075 | N15: 45128 | O15: 08:00 | P15: 14:00 | W15: 10
A16: ENAC | B16: SUSANA DEL PILAR | C16: SANTIBAÑEZ | D16: FIGUEROA | E16: 11993944-5 | F16: susana.santibanez@alumnos.enac.cl | G16: Técnico en Laboratorio Clínico y Banco de Sangre | H16: BANCO DE SANGRE | J16: Ramon Cesar Contreras Menendez | K16: 1ra rotación | L16: 5to año | M16: 45740 | N16: 45793 | O16: 08:00 | P16: 17:00 | V16: 45713 | W16: 9
A17: ENAC | B17: SANDRA CECILIA | C17: CONTRERAS | D17: LAZO | E17: 12239782-3 | F17: sandra.contreras@alumnos.enac.cl | G17: Técnico en Farmacia | H17: FARMACIA | I17: Eliana Pizarro | J17: JORGE VELOZ PEREZ | K17: 1ra rotación | L17: 2do año | M17: 45950 | N17: 46010 | O17: 08:00 | P17: 14:00 | V17: 45947 | W17: 8
A18: ENAC | B18: LISSETTI SUSANA | C18: CERDA | D18: CERDA | E18: 12259354-1 | F18: lissetti.cerda@alumnos.enac.cl | G18: Técnico en Enfermería | H18: Sector C 4º Piso - ESPECIALIDAD QUIRÚRGICA | I18: Marjorie Guzman | J18: CLAUDIA ZÚÑIGA AVENDAÑO | K18: 2da rotación | L18: 3er año | M18: 45922 | N18: 45961 | O18: 08:00 | P18: 08:00 | V18: 45908 | W18: 9
A19: ENAC | B19: LISSETTI SUSANA | C19: CERDA | D19: CERDA | E19: 12259354-1 | F19: lissetti.cerda@alumnos.enac.cl | G19: Técnico en Enfermería | H19: Sector C 4º Piso - ESPECIALIDAD QUIRÚRGICA | I19: MARJORIE GUZMAN | J19: CLAUDIA ZÚÑIGA AVENDAÑO | K19: 2da rotación | L19: 3er año | M19: 45922 | N19: 45961 | O19: 08:00 | P19: 08:00 | V19: 45908 | W19: 9
A20: ENAC | B20: MARCELO ALEJANDRO | C20: BASCUÑÁN | D20: URIBE | E20: 12829392-2 | F20: marcelo.bascunan@alumnos.enac.cl | G20: Técnico en Enfermería | H20: CIRUGÍA 2º PISO | J20: AMILEC LEIVA RIVERA | K20: 1ra rotación | L20: 1er año | M20: 46181 | N20: 46220 | O20: 08:00 | P20: 13:00 | V20: 46171 | W20: 9
A21: ENAC | B21: ROSA VICTORIA | C21: LAGOS | D21: LORCA | E21: 12852662-5 | F21: rosa.lagos@alumnos.enac.cl | G21: Técnico en Imagenología y Radioterapia | H21: Imagenología | J21: JORGE FRIAS PONCE | K21: 1ra rotación | L21: 2do año | M21: 45089 | N21: 45128 | O21: 08:00 | P21: 13:00
A22: Universidad de las Américas | B22: INGRID | C22: FUENTES | D22: PIZARRO | E22: 12907397-7 | F22: ingricita825@gmail.com | G22: Enfermería | H22: CIRUGIA 4TO PISO | J22: MARIA ANTONIETA MATAMOROS | K22: 6ta rotación | L22: 3er año | M22: 45159 | N22: 45177 | O22: 08:00 | P22: 17:00 | W22: 9
A23: Universidad de las Américas | B23: Josette | C23: Rojas | D23: Illanes | E23: 13013571-4 | F23: josita_rojas@hotmail.com | G23: Técnico en Enfermería | H23: UGA | I23: Daniela Rivera | J23: David Esparza Alvarado | K23: 2da rotación | L23: 3er año | M23: 45397 | N23: 45436 | O23: 08:00 | P23: 08:00 | V23: 45377 | W23: 9
A24: Universidad de las Américas | B24: Nicolas | C24: Leon | D24: Moncada | E24: 13050516-3 | F24: nicolasleon2000@gmail.com | G24: Técnico en Enfermería | H24: Urologia | I24: Marjorie Guzman | J24: David Esparza Alvarado | K24: 3ra rotación | L24: 3er año | M24: 45439 | N24: 45478 | O24: 08:00 | P24: 08:00 | V24: 45419 | W24: 10
A25: Universidad de las Américas | B25: Nicolas | C25: Leon | D25: Moncada | E25: 13050516-3 | F25: nicolasleon2000@gmail.com | G25: Técnico en Enfermería | H25: Urologia | I25: Marjorie Guzman | J25: David Esparza Alvarado | K25: 3ra rotación | L25: 3er año | M25: 45439 | N25: 45478 | O25: 08:00 | P25: 08:00 | V25: 45419 | W25: 10
A26: Universidad de las Américas | B26: PAOLA | C26: REYES | D26: ESCOBAR | E26: 13245503-1 | F26: PAOLAREYESESCOBAR@GMAIL.COM | G26: Técnico en Enfermería | H26: MEDICO QUIRURGICO | I26: Marjorie Guzman | J26: EDUARDO ZAMORA OTEÍZA | K26: 2da rotación | L26: 2do año | M26: 45033 | N26: 45044 | O26: 08:00 | P26: 12:00 | W26: 10
A27: ENAC | B27: ROSA CAROLINA | C27: ARAYA | D27: MARTÍNEZ | E27: 13338950-4 | F27: rosa.araya@alumnos.enac.cl | G27: Técnico en Farmacia | H27: FARMACIA | I27: Eliana Pizarro | J27: JORGE VELOZ PEREZ | K27: 1ra rotación | L27: 2do año | M27: 45950 | N27: 46010 | O27: 08:00 | P27: 14:00 | V27: 45947 | W27: 9
A28: Universidad Santo Tomás | B28: Karem Charlote | C28: Toledo | D28: Echeverría | E28: 13414222-7 | F28: karem.toledoe@alumnos.santotomas.cl | G28: Enfermería | H28: Area Pediatria Cuidados Medios Oncologicos | J28: Samantha Reyes | K28: 2da rotación | L28: 4to año | M28: 45600 | N28: 45612 | O28: 13:00 | P28: 17:00 | V28: 45399 | W28: 9
A29: Universidad Santo Tomás | B29: Karem Charlote | C29: Toledo | D29: Echeverría | E29: 13414222-7 | F29: karem.toledoe@alumnos.santotomas.cl | G29: Enfermería | H29: Suao | J29: Ximena González Cabrera | K29: 4ta rotación | L29: 4to año | M29: 45625 | N29: 45637 | O29: 13:00 | P29: 17:00 | V29: 45399 | W29: 9
A30: Universidad Santo Tomás | B30: Karem Charlotte | C30: Toledo | D30: Echeverría | E30: 13414222-7 | F30: karem.toledoe@alumnos.santotomas.cl | G30: Enfermería | H30: Chacabuco | J30: Priscilla Maulen Urzúa | K30: 2da rotación | L30: 3er año | M30: 45240 | N30: 45254 | O30: 13:00 | P30: 17:00 | W30: 8
A31: ENAC | B31: ORIELA SOLEDAD | C31: CERDA | D31: BARRERA | E31: 13439629-6 | F31: ocerdab@alumnos.enac.cl | G31: Técnico en Farmacia | H31: FARMACIA | J31: JASSON ESPINOZA CAICEDO | K31: 1ra rotación | L31: 5to año | M31: 45740 | N31: 45807 | O31: 08:00 | P31: 17:00 | V31: 45719 | W31: 10
A32: ENAC | B32: ROXANA BETSABÉ | C32: MORALES | D32: GATICA | E32: 13462525-2 | F32: roxana.morales.g@alumnos.enac.cl | G32: Técnico en Farmacia | H32: FARMACIA HOSPITAL | I32: ELIANA PIZARRO | J32: JORGE VELOZ PEREZ | L32: 3er año | M32: 46097 | N32: 46178 | O32: 08:00 | P32: 17:00 | V32: 46084 | W32: 9
A33: ENAC | B33: PAULINA ALEJANDRA | C33: ARAVENA | D33: PIZARRO | E33: 13468753-3 | F33: paravenap@alumnos.enac.cl | G33: Técnico en Enfermería | H33: ESPECIALIDAD QUIRÚRGICA | J33: FRANCISCO CORTÉS BUSTAMANTE | K33: 1ra rotación | L33: 3er año | M33: 45159 | N33: 45200 | O33: 08:00 | P33: 08:00 | W33: 8
A34: ENAC | B34: PAULINA ALEJANDRA | C34: ARAVENA | D34: PIZARRO | E34: 13468753-3 | F34: paravenap@alumnos.enac.cl | G34: Técnico en Enfermería | H34: Poli Gastroenterología | J34: FRANCISCO CORTÉS BUSTAMANTE | K34: 2da rotación | L34: 3er año | M34: 45201 | N34: 45240 | O34: 08:00 | P34: 17:30 | W34: 8
A35: ENAC | B35: Cheryl Caroline | C35: Pizarro | D35: Zúñiga | E35: 13498095-8 | F35: cheryl.pizarro@alumnos.enac.cl | G35: Técnico en Enfermería | H35: Medicina | J35: Francisco Cortés Bustamante | K35: 2da rotación | L35: 3er año | M35: 45558 | N35: 45598 | O35: 08:00 | P35: 08:00 | V35: 45527 | W35: 9
A36: Universidad de las Américas | B36: Natalia Alejandra | C36: Poblete | D36: Moreno | E36: 13558809-1 | F36: NATITA_ELIACITO@HOTMAIL.COM | G36: Técnico en Enfermería | H36: S. URGENCIA | I36: Liliana Vega | J36: Camila Gutiérrez | K36: 1ra rotación | L36: 3er año | M36: 44991 | N36: 45030 | O36: 08:00 | P36: 08:00 | W36: 10
A37: Universidad de las Américas | B37: KARINA VANESSA | C37: MUÑOZ | D37: SILVA | E37: 13663734-7 | F37: MUNOZSILVAKARINA@GMAIL.COM | G37: Fonoaudiología | H37: PEDIATRÍA | I37: CONSTANZA GODOY | J37: DANIELA LAVANDEROS | K37: 1ra rotación | L37: 5to año | M37: 45012 | N37: 45065 | O37: 08:00 | P37: 13:30 | W37: 9
A38: Universidad de las Américas | B38: PATRICIA INES | C38: DELGADO | D38: SANCHEZ | E38: 13666438-7 | F38: PATRICIA.DELGADO@EDU.UDLA.CL | G38: Kinesiología | H38: Medicina 2do piso d | I38: Paolo Reyes - Felipe Osses | J38: Paula Rojas | K38: 1ra rotación | L38: 5to año | M38: 45796 | N38: 45849 | O38: 08:00 | P38: 17:00 | V38: 45757 | W38: 9
A39: Universidad de las Américas | B39: XIMENA | C39: SALINAS | D39: ARIAS | E39: 13681140-1 | F39: XSALINAS50@HOTMAIL.COM | G39: Técnico en Enfermería | H39: URGENCIA | J39: BARBARA JAÑA | K39: 4ta rotación | L39: 3er año | M39: 45117 | N39: 45156 | O39: 08:00 | P39: 08:00 | W39: 10
A40: Universidad de las Américas | B40: MARIA | C40: MUÑOZ | D40: FUENTES | E40: 13694825-3 | F40: malejandra.munoz@edu.udla.cl | G40: Enfermería | H40: MEDICINA AGUDO 4°PISO SECTOR B | I40: Marjorie Guzman | J40: EDUARDO ZAMORA | K40: 8va rotación | L40: 3er año | M40: 45978 | N40: 46003 | O40: 08:00 | P40: 12:00 | V40: 45960 | W40: 10
...

Sheet Resumen uso día - año - mes
B2: 2023 | D2: 2024 | F2: 2025 | H2: 2026
B3: Mínimo | C3: Máximo | D3: Mínimo | E3: Máximo | F3: Mínimo | G3: Máximo | H3: Mínimo | I3: Máximo
A4: Enero | B4: =$B23 -> 2 | C4: =$B22 -> 45 | D4: =$B30 -> 2 | E4: =$B29 -> 8 | F4: =$B37 -> 16 | G4: =$B36 -> 79 | H4: =$B44 -> 42 | I4: =$B43 -> 68
A5: Febrero | B5: =$AG23 -> 2 | C5: =$AG22 -> 12 | D5: =$AG30 -> 2 | E5: =$AG29 -> 2 | F5: =$AG37 -> 68 | G5: =$AG36 -> 120 | H5: =$AG44 -> 41 | I5: =$AG43 -> 70
A6: Marzo | B6: =$BI23 -> 11 | C6: =$BI22 -> 219 | D6: =$BJ30 -> 2 | E6: =$BJ29 -> 89 | F6: =$BI37 -> 121 | G6: =$BI36 -> 391 | H6: =$BI44 -> 37 | I6: =$BI43 -> 426
A7: Abril | B7: =$CN23 -> 197 | C7: =$CN22 -> 280 | D7: =$CO30 -> 115 | E7: =$CO29 -> 245 | F7: =$CN37 -> 335 | G7: =$CN36 -> 426 | H7: =$CN44 -> 298 | I7: =$CN43 -> 450
A8: Mayo | B8: =$DR23 -> 196 | C8: =$DR22 -> 260 | D8: =$DS30 -> 233 | E8: =$DS29 -> 394 | F8: =$DR37 -> 402 | G8: =$DR36 -> 527 | H8: =$DR44 -> 269 | I8: =$DR43 -> 381
A9: Junio | B9: =$EW23 -> 211 | C9: =$EW22 -> 278 | D9: =$EX30 -> 245 | E9: =$EX29 -> 343 | F9: =$EW37 -> 252 | G9: =$EW36 -> 489 | H9: =$EW44 -> 241 | I9: =$EW43 -> 358
A10: Julio | B10: =$GA23 -> 91 | C10: =$GA22 -> 218 | D10: =$GB30 -> 75 | E10: =$GB29 -> 248 | F10: =$GA37 -> 121 | G10: =$GA36 -> 267 | H10: =$GA44 -> 92 | I10: =$GA43 -> 280
A11: Agosto | B11: =$HF23 -> 107 | C11: =$HF22 -> 389 | D11: =$HG30 -> 65 | E11: =$HG29 -> 285 | F11: =$HF37 -> 121 | G11: =$HF36 -> 351 | H11: =$HF44 -> 47 | I11: =$HF43 -> 105
A12: Septiembre | B12: =$IK23 -> 359 | C12: =$IK22 -> 409 | D12: =$IL30 -> 229 | E12: =$IL29 -> 315 | F12: =$IK37 -> 236 | G12: =$IK36 -> 421 | H12: =$IK44 -> 4 | I12: =$IK43 -> 45
A13: Octubre | B13: =$JO23 -> 359 | C13: =$JO22 -> 520 | D13: =$JP30 -> 227 | E13: =$JP29 -> 465 | F13: =$JO37 -> 299 | G13: =$JO36 -> 488 | H13: =$JO44 -> 1 | I13: =$JO43 -> 4
A14: Noviembre | B14: =$KT23 -> 337 | C14: =$KT22 -> 518 | D14: =$KU30 -> 221 | E14: =$KU29 -> 441 | F14: =$KT37 -> 209 | G14: =$KT36 -> 404 | H14: =$KT44 -> 0 | I14: =$KT43 -> 0
A15: Diciembre | B15: =$LX23 -> 17 | C15: =$LX22 -> 326 | D15: =$LY30 -> 24 | E15: =$LY29 -> 339 | F15: =$LX37 -> 35 | G15: =$LX36 -> 277 | H15: =$LX44 -> 0 | I15: =$LX43 -> 0
A18: AÑO 2023 | B18: ENERO | AG18: FEBRERO | BI18: MARZO | CN18: ABRIL | DR18: MAYO | EW18: JUNIO | GA18: JULIO | HF18: AGOSTO | IK18: SEPTIEMBRE | JO18: OCTUBRE | KT18: NOVIEMBRE | LX18: DICIEMBRE
B19: Domingo | C19: Lunes | D19: Martes | E19: Miércoles | F19: Jueves | G19: Viernes | H19: Sábado | I19: Domingo | J19: Lunes | K19: Martes | L19: Miércoles | M19: Jueves | N19: Viernes | O19: Sábado | P19: Domingo | Q19: Lunes | R19: Martes | S19: Miércoles | T19: Jueves | U19: Viernes | V19: Sábado | W19: Domingo | X19: Lunes | Y19: Martes | Z19: Miércoles | AA19: Jueves | AB19: Viernes | AC19: Sábado | AD19: Domingo | AE19: Lunes | AF19: Martes | AG19: Miércoles | AH19: Jueves | AI19: Viernes | AJ19: Sábado | AK19: Domingo | AL19: Lunes | AM19: Martes | AN19: Miércoles | AO19: Jueves | AP19: Viernes | AQ19: Sábado | AR19: Domingo | AS19: Lunes | AT19: Martes | AU19: Miércoles | AV19: Jueves | AW19: Viernes | AX19: Sábado | AY19: Domingo | AZ19: Lunes | BA19: Martes | BB19: Miércoles | BC19: Jueves | BD19: Viernes | BE19: Sábado | BF19: Domingo | BG19: Lunes | BH19: Martes | BI19: Miércoles | BJ19: Jueves | BK19: Viernes | BL19: Sábado | BM19: Domingo | BN19: Lunes | BO19: Martes | BP19: Miércoles | BQ19: Jueves | BR19: Viernes | BS19: Sábado | BT19: Domingo | BU19: Lunes | BV19: Martes | BW19: Miércoles | BX19: Jueves | BY19: Viernes | BZ19: Sábado | CA19: Domingo | CB19: Lunes | CC19: Martes | CD19: Miércoles | CE19: Jueves | CF19: Viernes | CG19: Sábado | CH19: Domingo | CI19: Lunes | CJ19: Martes | CK19: Miércoles | CL19: Jueves | CM19: Viernes | CN19: Sábado | CO19: Domingo | CP19: Lunes | CQ19: Martes | CR19: Miércoles | CS19: Jueves | CT19: Viernes | CU19: Sábado | CV19: Domingo | CW19: Lunes | CX19: Martes | CY19: Miércoles | CZ19: Jueves | DA19: Viernes | DB19: Sábado | DC19: Domingo | DD19: Lunes | DE19: Martes | DF19: Miércoles | DG19: Jueves | DH19: Viernes | DI19: Sábado | DJ19: Domingo | DK19: Lunes | DL19: Martes | DM19: Miércoles | DN19: Jueves | DO19: Viernes | DP19: Sábado | DQ19: Domingo | DR19: Lunes | DS19: Martes | DT19: Miércoles | DU19: Jueves | DV19: Viernes | DW19: Sábado | DX19: Domingo | DY19: Lunes | DZ19: Martes | EA19: Miércoles | EB19: Jueves | EC19: Viernes | ED19: Sábado | EE19: Domingo | EF19: Lunes | EG19: Martes | EH19: Miércoles | EI19: Jueves | EJ19: Viernes | EK19: Sábado | EL19: Domingo | EM19: Lunes | EN19: Martes | EO19: Miércoles | EP19: Jueves | EQ19: Viernes | ER19: Sábado | ES19: Domingo | ET19: Lunes | EU19: Martes | EV19: Miércoles | EW19: Jueves | EX19: Viernes | EY19: Sábado | EZ19: Domingo | FA19: Lunes | FB19: Martes | FC19: Miércoles | FD19: Jueves | FE19: Viernes | FF19: Sábado | FG19: Domingo | FH19: Lunes | FI19: Martes | FJ19: Miércoles | FK19: Jueves | FL19: Viernes | FM19: Sábado | FN19: Domingo | FO19: Lunes | FP19: Martes | FQ19: Miércoles | FR19: Jueves | FS19: Viernes | FT19: Sábado | FU19: Domingo | FV19: Lunes | FW19: Martes | FX19: Miércoles | FY19: Jueves | FZ19: Viernes | GA19: Sábado | GB19: Domingo | GC19: Lunes | GD19: Martes | GE19: Miércoles | GF19: Jueves | GG19: Viernes | GH19: Sábado | GI19: Domingo | GJ19: Lunes | GK19: Martes | GL19: Miércoles | GM19: Jueves | GN19: Viernes | GO19: Sábado | GP19: Domingo | GQ19: Lunes | GR19: Martes | GS19: Miércoles | GT19: Jueves | GU19: Viernes | GV19: Sábado | GW19: Domingo | GX19: Lunes | GY19: Martes | GZ19: Miércoles | HA19: Jueves | HB19: Viernes | HC19: Sábado | HD19: Domingo | HE19: Lunes | HF19: Martes | HG19: Miércoles | HH19: Jueves | HI19: Viernes | HJ19: Sábado | HK19: Domingo | HL19: Lunes | HM19: Martes | HN19: Miércoles | HO19: Jueves | HP19: Viernes | HQ19: Sábado | HR19: Domingo | HS19: Lunes | HT19: Martes | HU19: Miércoles | HV19: Jueves | HW19: Viernes | HX19: Sábado | HY19: Domingo | HZ19: Lunes | IA19: Martes | IB19: Miércoles | IC19: Jueves | ID19: Viernes | IE19: Sábado | IF19: Domingo | IG19: Lunes | IH19: Martes | II19: Miércoles | IJ19: Jueves | IK19: Viernes | IL19: Sábado | IM19: Domingo | IN19: Lunes | IO19: Martes | IP19: Miércoles | IQ19: Jueves | IR19: Viernes | IS19: Sábado | IT19: Domingo | IU19: Lunes | IV19: Martes | IW19: Miércoles | IX19: Jueves | IY19: Viernes | IZ19: Sábado | JA19: Domingo | JB19: Lunes | JC19: Martes | JD19: Miércoles | JE19: Jueves | JF19: Viernes | JG19: Sábado | JH19: Domingo | JI19: Lunes | JJ19: Martes | JK19: Miércoles | JL19: Jueves | JM19: Viernes | JN19: Sábado | JO19: Domingo | JP19: Lunes | JQ19: Martes | JR19: Miércoles | JS19: Jueves | JT19: Viernes | JU19: Sábado | JV19: Domingo | JW19: Lunes | JX19: Martes | JY19: Miércoles | JZ19: Jueves | KA19: Viernes | KB19: Sábado | KC19: Domingo | KD19: Lunes | KE19: Martes | KF19: Miércoles | KG19: Jueves | KH19: Viernes | KI19: Sábado | KJ19: Domingo | KK19: Lunes | KL19: Martes | KM19: Miércoles | KN19: Jueves | KO19: Viernes | KP19: Sábado | KQ19: Domingo | KR19: Lunes | KS19: Martes | KT19: Miércoles | KU19: Jueves | KV19: Viernes | KW19: Sábado | KX19: Domingo | KY19: Lunes | KZ19: Martes | LA19: Miércoles | LB19: Jueves | LC19: Viernes | LD19: Sábado | LE19: Domingo | LF19: Lunes | LG19: Martes | LH19: Miércoles | LI19: Jueves | LJ19: Viernes | LK19: Sábado | LL19: Domingo | LM19: Lunes | LN19: Martes | LO19: Miércoles | LP19: Jueves | LQ19: Viernes | LR19: Sábado | LS19: Domingo | LT19: Lunes | LU19: Martes | LV19: Miércoles | LW19: Jueves | LX19: Viernes | LY19: Sábado | LZ19: Domingo | MA19: Lunes | MB19: Martes | MC19: Miércoles | MD19: Jueves | ME19: Viernes | MF19: Sábado | MG19: Domingo | MH19: Lunes | MI19: Martes | MJ19: Miércoles | MK19: Jueves | ML19: Viernes | MM19: Sábado | MN19: Domingo | MO19: Lunes | MP19: Martes | MQ19: Miércoles | MR19: Jueves | MS19: Viernes | MT19: Sábado | MU19: Domingo | MV19: Lunes | MW19: Martes | MX19: Miércoles | MY19: Jueves | MZ19: Viernes | NA19: Sábado | NB19: Domingo
B20: 44927 | C20: 44928 | D20: 44929 | E20: 44930 | F20: 44931 | G20: 44932 | H20: 44933 | I20: 44934 | J20: 44935 | K20: 44936 | L20: 44937 | M20: 44938 | N20: 44939 | O20: 44940 | P20: 44941 | Q20: 44942 | R20: 44943 | S20: 44944 | T20: 44945 | U20: 44946 | V20: 44947 | W20: 44948 | X20: 44949 | Y20: 44950 | Z20: 44951 | AA20: 44952 | AB20: 44953 | AC20: 44954 | AD20: 44955 | AE20: 44956 | AF20: 44957 | AG20: 44958 | AH20: 44959 | AI20: 44960 | AJ20: 44961 | AK20: 44962 | AL20: 44963 | AM20: 44964 | AN20: 44965 | AO20: 44966 | AP20: 44967 | AQ20: 44968 | AR20: 44969 | AS20: 44970 | AT20: 44971 | AU20: 44972 | AV20: 44973 | AW20: 44974 | AX20: 44975 | AY20: 44976 | AZ20: 44977 | BA20: 44978 | BB20: 44979 | BC20: 44980 | BD20: 44981 | BE20: 44982 | BF20: 44983 | BG20: 44984 | BH20: 44985 | BI20: 44986 | BJ20: 44987 | BK20: 44988 | BL20: 44989 | BM20: 44990 | BN20: 44991 | BO20: 44992 | BP20: 44993 | BQ20: 44994 | BR20: 44995 | BS20: 44996 | BT20: 44997 | BU20: 44998 | BV20: 44999 | BW20: 45000 | BX20: 45001 | BY20: 45002 | BZ20: 45003 | CA20: 45004 | CB20: 45005 | CC20: 45006 | CD20: 45007 | CE20: 45008 | CF20: 45009 | CG20: 45010 | CH20: 45011 | CI20: 45012 | CJ20: 45013 | CK20: 45014 | CL20: 45015 | CM20: 45016 | CN20: 45017 | CO20: 45018 | CP20: 45019 | CQ20: 45020 | CR20: 45021 | CS20: 45022 | CT20: 45023 | CU20: 45024 | CV20: 45025 | CW20: 45026 | CX20: 45027 | CY20: 45028 | CZ20: 45029 | DA20: 45030 | DB20: 45031 | DC20: 45032 | DD20: 45033 | DE20: 45034 | DF20: 45035 | DG20: 45036 | DH20: 45037 | DI20: 45038 | DJ20: 45039 | DK20: 45040 | DL20: 45041 | DM20: 45042 | DN20: 45043 | DO20: 45044 | DP20: 45045 | DQ20: 45046 | DR20: 45047 | DS20: 45048 | DT20: 45049 | DU20: 45050 | DV20: 45051 | DW20: 45052 | DX20: 45053 | DY20: 45054 | DZ20: 45055 | EA20: 45056 | EB20: 45057 | EC20: 45058 | ED20: 45059 | EE20: 45060 | EF20: 45061 | EG20: 45062 | EH20: 45063 | EI20: 45064 | EJ20: 45065 | EK20: 45066 | EL20: 45067 | EM20: 45068 | EN20: 45069 | EO20: 45070 | EP20: 45071 | EQ20: 45072 | ER20: 45073 | ES20: 45074 | ET20: 45075 | EU20: 45076 | EV20: 45077 | EW20: 45078 | EX20: 45079 | EY20: 45080 | EZ20: 45081 | FA20: 45082 | FB20: 45083 | FC20: 45084 | FD20: 45085 | FE20: 45086 | FF20: 45087 | FG20: 45088 | FH20: 45089 | FI20: 45090 | FJ20: 45091 | FK20: 45092 | FL20: 45093 | FM20: 45094 | FN20: 45095 | FO20: 45096 | FP20: 45097 | FQ20: 45098 | FR20: 45099 | FS20: 45100 | FT20: 45101 | FU20: 45102 | FV20: 45103 | FW20: 45104 | FX20: 45105 | FY20: 45106 | FZ20: 45107 | GA20: 45108 | GB20: 45109 | GC20: 45110 | GD20: 45111 | GE20: 45112 | GF20: 45113 | GG20: 45114 | GH20: 45115 | GI20: 45116 | GJ20: 45117 | GK20: 45118 | GL20: 45119 | GM20: 45120 | GN20: 45121 | GO20: 45122 | GP20: 45123 | GQ20: 45124 | GR20: 45125 | GS20: 45126 | GT20: 45127 | GU20: 45128 | GV20: 45129 | GW20: 45130 | GX20: 45131 | GY20: 45132 | GZ20: 45133 | HA20: 45134 | HB20: 45135 | HC20: 45136 | HD20: 45137 | HE20: 45138 | HF20: 45139 | HG20: 45140 | HH20: 45141 | HI20: 45142 | HJ20: 45143 | HK20: 45144 | HL20: 45145 | HM20: 45146 | HN20: 45147 | HO20: 45148 | HP20: 45149 | HQ20: 45150 | HR20: 45151 | HS20: 45152 | HT20: 45153 | HU20: 45154 | HV20: 45155 | HW20: 45156 | HX20: 45157 | HY20: 45158 | HZ20: 45159 | IA20: 45160 | IB20: 45161 | IC20: 45162 | ID20: 45163 | IE20: 45164 | IF20: 45165 | IG20: 45166 | IH20: 45167 | II20: 45168 | IJ20: 45169 | IK20: 45170 | IL20: 45171 | IM20: 45172 | IN20: 45173 | IO20: 45174 | IP20: 45175 | IQ20: 45176 | IR20: 45177 | IS20: 45178 | IT20: 45179 | IU20: 45180 | IV20: 45181 | IW20: 45182 | IX20: 45183 | IY20: 45184 | IZ20: 45185 | JA20: 45186 | JB20: 45187 | JC20: 45188 | JD20: 45189 | JE20: 45190 | JF20: 45191 | JG20: 45192 | JH20: 45193 | JI20: 45194 | JJ20: 45195 | JK20: 45196 | JL20: 45197 | JM20: 45198 | JN20: 45199 | JO20: 45200 | JP20: 45201 | JQ20: 45202 | JR20: 45203 | JS20: 45204 | JT20: 45205 | JU20: 45206 | JV20: 45207 | JW20: 45208 | JX20: 45209 | JY20: 45210 | JZ20: 45211 | KA20: 45212 | KB20: 45213 | KC20: 45214 | KD20: 45215 | KE20: 45216 | KF20: 45217 | KG20: 45218 | KH20: 45219 | KI20: 45220 | KJ20: 45221 | KK20: 45222 | KL20: 45223 | KM20: 45224 | KN20: 45225 | KO20: 45226 | KP20: 45227 | KQ20: 45228 | KR20: 45229 | KS20: 45230 | KT20: 45231 | KU20: 45232 | KV20: 45233 | KW20: 45234 | KX20: 45235 | KY20: 45236 | KZ20: 45237 | LA20: 45238 | LB20: 45239 | LC20: 45240 | LD20: 45241 | LE20: 45242 | LF20: 45243 | LG20: 45244 | LH20: 45245 | LI20: 45246 | LJ20: 45247 | LK20: 45248 | LL20: 45249 | LM20: 45250 | LN20: 45251 | LO20: 45252 | LP20: 45253 | LQ20: 45254 | LR20: 45255 | LS20: 45256 | LT20: 45257 | LU20: 45258 | LV20: 45259 | LW20: 45260 | LX20: 45261 | LY20: 45262 | LZ20: 45263 | MA20: 45264 | MB20: 45265 | MC20: 45266 | MD20: 45267 | ME20: 45268 | MF20: 45269 | MG20: 45270 | MH20: 45271 | MI20: 45272 | MJ20: 45273 | MK20: 45274 | ML20: 45275 | MM20: 45276 | MN20: 45277 | MO20: 45278 | MP20: 45279 | MQ20: 45280 | MR20: 45281 | MS20: 45282 | MT20: 45283 | MU20: 45284 | MV20: 45285 | MW20: 45286 | MX20: 45287 | MY20: 45288 | MZ20: 45289 | NA20: 45290 | NB20: 45291
A21: Máximo estudiantes simultáneos día | B21: =COUNTIFS('HISTÓRICO 2023-2026'!$M:$M,"<="&B$20,'HISTÓRICO 2023-2026'!$N:$N,">="&B$20) -> 16 | C21: =COUNTIFS('HISTÓRICO 2023-2026'!$M:$M,"<="&C$20,'HISTÓRICO 2023-2026'!$N:$N,">="&C$20) -> 16 | D21: =COUNTIFS('HISTÓRICO 2023-2026'!$M:$M,"<="&D$20,'HISTÓRICO 2023-2026'!$N:$N,">="&D$20) -> 17 | E21: =COUNTIFS('HISTÓRICO 2023-2026'!$M:$M,"<="&E$20,'HISTÓRICO 2023-2026'!$N:$N,">="&E$20) -> 12 | F21: =COUNTIFS('HISTÓRICO 2023-2026'!$M:$M,"<="&F$20,'HISTÓRICO 2023-2026'!$N:$N,">="&F$20) -> 28 | G21: =COUNTIFS('HISTÓRICO 2023-2026'!$M:$M,"<="&G$20,'HISTÓRICO 2023-2026'!$N:$N,">="&G$20) -> 22 | H21: =COUNTIFS('HISTÓRICO 2023-2026'!$M:$M,"<="&H$20,'HISTÓRICO 2023-2026'!$N:$N,">="&H$20) -> 12 | I21: =COUNTIFS('HISTÓRICO 2023-2026'!$M:$M,"<="&I$20,'HISTÓRICO 2023-2026'!$N:$N,">="&I$20) -> 12 | ... NB21: =COUNTIFS('HISTÓRICO 2023-2026'!$M:$M,"<="&NB$20,'HISTÓRICO 2023-2026'!$N:$N,">="&NB$20) -> 17
A22: Máximo estudiantes simultáneos mes | B22: =MAX(B21:AF21) -> 45 | AG22: =MAX(AG21:BH21) -> 12 | BI22: =MAX(BI21:CM21) -> 219 | CN22: =MAX(CN21:DQ21) -> 280 | DR22: =MAX(DR21:EV21) -> 260 | EW22: =MAX(EW21:FZ21) -> 278 | GA22: =MAX(GA21:HE21) -> 218 | HF22: =MAX(HF21:IJ21) -> 389 | IK22: =MAX(IK21:JN21) -> 409 | JO22: =MAX(JO21:KS21) -> 520 | KT22: =MAX(KT21:LW21) -> 518 | LX22: =MAX(LX21:NB21) -> 326
A23: Mínimo estudiantes simultáneos mes | B23: {=MIN(IF(B21:AF21>0, B21:AF21))} -> 2 | AG23: {=MIN(IF(AG21:BH21>0, AG21:BH21))} -> 2 | BI23: {=MIN(IF(BI21:CM21>0, BI21:CM21))} -> 11 | CN23: {=MIN(IF(CN21:DQ21>0, CN21:DQ21))} -> 197 | DR23: {=MIN(IF(DR21:EV21>0, DR21:EV21))} -> 196 | EW23: {=MIN(IF(EW21:FZ21>0, EW21:FZ21))} -> 211 | GA23: {=MIN(IF(GA21:HE21>0, GA21:HE21))} -> 91 | HF23: {=MIN(IF(HF21:IJ21>0, HF21:IJ21))} -> 107 | IK23: {=MIN(IF(IK21:JN21>0, IK21:JN21))} -> 359 | JO23: {=MIN(IF(JO21:KS21>0, JO21:KS21))} -> 359 | KT23: {=MIN(IF(KT21:LW21>0, KT21:LW21))} -> 337 | LX23: {=MIN(IF(LX21:NB21>0, LX21:NB21))} -> 17
A25: AÑO 2024 | B25: ENERO | AG25: FEBRERO | BJ25: MARZO | CO25: ABRIL | DS25: MAYO | EX25: JUNIO | GB25: JULIO | HG25: AGOSTO | IL25: SEPTIEMBRE | JP25: OCTUBRE | KU25: NOVIEMBRE | LY25: DICIEMBRE
B26: Lunes | C26: Martes | D26: Miércoles | E26: Jueves | F26: Viernes | G26: Sábado | H26: Domingo | I26: Lunes | J26: Martes | K26: Miércoles | L26: Jueves | M26: Viernes | N26: Sábado | O26: Domingo | P26: Lunes | Q26: Martes | R26: Miércoles | S26: Jueves | T26: Viernes | U26: Sábado | V26: Domingo | W26: Lunes | X26: Martes | Y26: Miércoles | Z26: Jueves | AA26: Viernes | AB26: Sábado | AC26: Domingo | AD26: Lunes | AE26: Martes | AF26: Miércoles | AG26: Jueves | AH26: Viernes | AI26: Sábado | AJ26: Domingo | AK26: Lunes | AL26: Martes | AM26: Miércoles | AN26: Jueves | AO26: Viernes | AP26: Sábado | AQ26: Domingo | AR26: Lunes | AS26: Martes | AT26: Miércoles | AU26: Jueves | AV26: Viernes | AW26: Sábado | AX26: Domingo | AY26: Lunes | AZ26: Martes | BA26: Miércoles | BB26: Jueves | BC26: Viernes | BD26: Sábado | BE26: Domingo | BF26: Lunes | BG26: Martes | BH26: Miércoles | BI26: Jueves | BJ26: Viernes | BK26: Sábado | BL26: Domingo | BM26: Lunes | BN26: Martes | BO26: Miércoles | BP26: Jueves | BQ26: Viernes | BR26: Sábado | BS26: Domingo | BT26: Lunes | BU26: Martes | BV26: Miércoles | BW26: Jueves | BX26: Viernes | BY26: Sábado | BZ26: Domingo | CA26: Lunes | CB26: Martes | CC26: Miércoles | CD26: Jueves | CE26: Viernes | CF26: Sábado | CG26: Domingo | CH26: Lunes | CI26: Martes | CJ26: Miércoles | CK26: Jueves | CL26: Viernes | CM26: Sábado | CN26: Domingo | CO26: Lunes | CP26: Martes | CQ26: Miércoles | CR26: Jueves | CS26: Viernes | CT26: Sábado | CU26: Domingo | CV26: Lunes | CW26: Martes | CX26: Miércoles | CY26: Jueves | CZ26: Viernes | DA26: Sábado | DB26: Domingo | DC26: Lunes | DD26: Martes | DE26: Miércoles | DF26: Jueves | DG26: Viernes | DH26: Sábado | DI26: Domingo | DJ26: Lunes | DK26: Martes | DL26: Miércoles | DM26: Jueves | DN26: Viernes | DO26: Sábado | DP26: Domingo | DQ26: Lunes | DR26: Martes | DS26: Miércoles | DT26: Jueves | DU26: Viernes | DV26: Sábado | DW26: Domingo | DX26: Lunes | DY26: Martes | DZ26: Miércoles | EA26: Jueves | EB26: Viernes | EC26: Sábado | ED26: Domingo | EE26: Lunes | EF26: Martes | EG26: Miércoles | EH26: Jueves | EI26: Viernes | EJ26: Sábado | EK26: Domingo | EL26: Lunes | EM26: Martes | EN26: Miércoles | EO26: Jueves | EP26: Viernes | EQ26: Sábado | ER26: Domingo | ES26: Lunes | ET26: Martes | EU26: Miércoles | EV26: Jueves | EW26: Viernes | EX26: Sábado | EY26: Domingo | EZ26: Lunes | FA26: Martes | FB26: Miércoles | FC26: Jueves | FD26: Viernes | FE26: Sábado | FF26: Domingo | FG26: Lunes | FH26: Martes | FI26: Miércoles | FJ26: Jueves | FK26: Viernes | FL26: Sábado | FM26: Domingo | FN26: Lunes | FO26: Martes | FP26: Miércoles | FQ26: Jueves | FR26: Viernes | FS26: Sábado | FT26: Domingo | FU26: Lunes | FV26: Martes | FW26: Miércoles | FX26: Jueves | FY26: Viernes | FZ26: Sábado | GA26: Domingo | GB26: Lunes | GC26: Martes | GD26: Miércoles | GE26: Jueves | GF26: Viernes | GG26: Sábado | GH26: Domingo | GI26: Lunes | GJ26: Martes | GK26: Miércoles | GL26: Jueves | GM26: Viernes | GN26: Sábado | GO26: Domingo | GP26: Lunes | GQ26: Martes | GR26: Miércoles | GS26: Jueves | GT26: Viernes | GU26: Sábado | GV26: Domingo | GW26: Lunes | GX26: Martes | GY26: Miércoles | GZ26: Jueves | HA26: Viernes | HB26: Sábado | HC26: Domingo | HD26: Lunes | HE26: Martes | HF26: Miércoles | HG26: Jueves | HH26: Viernes | HI26: Sábado | HJ26: Domingo | HK26: Lunes | HL26: Martes | HM26: Miércoles | HN26: Jueves | HO26: Viernes | HP26: Sábado | HQ26: Domingo | HR26: Lunes | HS26: Martes | HT26: Miércoles | HU26: Jueves | HV26: Viernes | HW26: Sábado | HX26: Domingo | HY26: Lunes | HZ26: Martes | IA26: Miércoles | IB26: Jueves | IC26: Viernes | ID26: Sábado | IE26: Domingo | IF26: Lunes | IG26: Martes | IH26: Miércoles | II26: Jueves | IJ26: Viernes | IK26: Sábado | IL26: Domingo | IM26: Lunes | IN26: Martes | IO26: Miércoles | IP26: Jueves | IQ26: Viernes | IR26: Sábado | IS26: Domingo | IT26: Lunes | IU26: Martes | IV26: Miércoles | IW26: Jueves | IX26: Viernes | IY26: Sábado | IZ26: Domingo | JA26: Lunes | JB26: Martes | JC26: Miércoles | JD26: Jueves | JE26: Viernes | JF26: Sábado | JG26: Domingo | JH26: Lunes | JI26: Martes | JJ26: Miércoles | JK26: Jueves | JL26: Viernes | JM26: Sábado | JN26: Domingo | JO26: Lunes | JP26: Martes | JQ26: Miércoles | JR26: Jueves | JS26: Viernes | JT26: Sábado | JU26: Domingo | JV26: Lunes | JW26: Martes | JX26: Miércoles | JY26: Jueves | JZ26: Viernes | KA26: Sábado | KB26: Domingo | KC26: Lunes | KD26: Martes | KE26: Miércoles | KF26: Jueves | KG26: Viernes | KH26: Sábado | KI26: Domingo | KJ26: Lunes | KK26: Martes | KL26: Miércoles | KM26: Jueves | KN26: Viernes | KO26: Sábado | KP26: Domingo | KQ26: Lunes | KR26: Martes | KS26: Miércoles | KT26: Jueves | KU26: Viernes | KV26: Sábado | KW26: Domingo | KX26: Lunes | KY26: Martes | KZ26: Miércoles | LA26: Jueves | LB26: Viernes | LC26: Sábado | LD26: Domingo | LE26: Lunes | LF26: Martes | LG26: Miércoles | LH26: Jueves | LI26: Viernes | LJ26: Sábado | LK26: Domingo | LL26: Lunes | LM26: Martes | LN26: Miércoles | LO26: Jueves | LP26: Viernes | LQ26: Sábado | LR26: Domingo | LS26: Lunes | LT26: Martes | LU26: Miércoles | LV26: Jueves | LW26: Viernes | LX26: Sábado | LY26: Domingo | LZ26: Lunes | MA26: Martes | MB26: Miércoles | MC26: Jueves | MD26: Viernes | ME26: Sábado | MF26: Domingo | MG26: Lunes | MH26: Martes | MI26: Miércoles | MJ26: Jueves | MK26: Viernes | ML26: Sábado | MM26: Domingo | MN26: Lunes | MO26: Martes | MP26: Miércoles | MQ26: Jueves | MR26: Viernes | MS26: Sábado | MT26: Domingo | MU26: Lunes | MV26: Martes | MW26: Miércoles | MX26: Jueves | MY26: Viernes | MZ26: Sábado | NA26: Domingo | NB26: Lunes | NC26: Martes
B27: 45292 | C27: 45293 | D27: 45294 | E27: 45295 | F27: 45296 | G27: 45297 | H27: 45298 | I27: 45299 | J27: 45300 | K27: 45301 | L27: 45302 | M27: 45303 | N27: 45304 | O27: 45305 | P27: 45306 | Q27: 45307 | R27: 45308 | S27: 45309 | T27: 45310 | U27: 45311 | V27: 45312 | W27: 45313 | X27: 45314 | Y27: 45315 | Z27: 45316 | AA27: 45317 | AB27: 45318 | AC27: 45319 | AD27: 45320 | AE27: 45321 | AF27: 45322 | AG27: 45323 | AH27: 45324 | AI27: 45325 | AJ27: 45326 | AK27: 45327 | AL27: 45328 | AM27: 45329 | AN27: 45330 | AO27: 45331 | AP27: 45332 | AQ27: 45333 | AR27: 45334 | AS27: 45335 | AT27: 45336 | AU27: 45337 | AV27: 45338 | AW27: 45339 | AX27: 45340 | AY27: 45341 | AZ27: 45342 | BA27: 45343 | BB27: 45344 | BC27: 45345 | BD27: 45346 | BE27: 45347 | BF27: 45348 | BG27: 45349 | BH27: 45350 | BI27: 45351 | BJ27: 45352 | BK27: 45353 | BL27: 45354 | BM27: 45355 | BN27: 45356 | BO27: 45357 | BP27: 45358 | BQ27: 45359 | BR27: 45360 | BS27: 45361 | BT27: 45362 | BU27: 45363 | BV27: 45364 | BW27: 45365 | BX27: 45366 | BY27: 45367 | BZ27: 45368 | CA27: 45369 | CB27: 45370 | CC27: 45371 | CD27: 45372 | CE27: 45373 | CF27: 45374 | CG27: 45375 | CH27: 45376 | CI27: 45377 | CJ27: 45378 | CK27: 45379 | CL27: 45380 | CM27: 45381 | CN27: 45382 | CO27: 45383 | CP27: 45384 | CQ27: 45385 | CR27: 45386 | CS27: 45387 | CT27: 45388 | CU27: 45389 | CV27: 45390 | CW27: 45391 | CX27: 45392 | CY27: 45393 | CZ27: 45394 | DA27: 45395 | DB27: 45396 | DC27: 45397 | DD27: 45398 | DE27: 45399 | DF27: 45400 | DG27: 45401 | DH27: 45402 | DI27: 45403 | DJ27: 45404 | DK27: 45405 | DL27: 45406 | DM27: 45407 | DN27: 45408 | DO27: 45409 | DP27: 45410 | DQ27: 45411 | DR27: 45412 | DS27: 45413 | DT27: 45414 | DU27: 45415 | DV27: 45416 | DW27: 45417 | DX27: 45418 | DY27: 45419 | DZ27: 45420 | EA27: 45421 | EB27: 45422 | EC27: 45423 | ED27: 45424 | EE27: 45425 | EF27: 45426 | EG27: 45427 | EH27: 45428 | EI27: 45429 | EJ27: 45430 | EK27: 45431 | EL27: 45432 | EM27: 45433 | EN27: 45434 | EO27: 45435 | EP27: 45436 | EQ27: 45437 | ER27: 45438 | ES27: 45439 | ET27: 45440 | EU27: 45441 | EV27: 45442 | EW27: 45443 | EX27: 45444 | EY27: 45445 | EZ27: 45446 | FA27: 45447 | FB27: 45448 | FC27: 45449 | FD27: 45450 | FE27: 45451 | FF27: 45452 | FG27: 45453 | FH27: 45454 | FI27: 45455 | FJ27: 45456 | FK27: 45457 | FL27: 45458 | FM27: 45459 | FN27: 45460 | FO27: 45461 | FP27: 45462 | FQ27: 45463 | FR27: 45464 | FS27: 45465 | FT27: 45466 | FU27: 45467 | FV27: 45468 | FW27: 45469 | FX27: 45470 | FY27: 45471 | FZ27: 45472 | GA27: 45473 | GB27: 45474 | GC27: 45475 | GD27: 45476 | GE27: 45477 | GF27: 45478 | GG27: 45479 | GH27: 45480 | GI27: 45481 | GJ27: 45482 | GK27: 45483 | GL27: 45484 | GM27: 45485 | GN27: 45486 | GO27: 45487 | GP27: 45488 | GQ27: 45489 | GR27: 45490 | GS27: 45491 | GT27: 45492 | GU27: 45493 | GV27: 45494 | GW27: 45495 | GX27: 45496 | GY27: 45497 | GZ27: 45498 | HA27: 45499 | HB27: 45500 | HC27: 45501 | HD27: 45502 | HE27: 45503 | HF27: 45504 | HG27: 45505 | HH27: 45506 | HI27: 45507 | HJ27: 45508 | HK27: 45509 | HL27: 45510 | HM27: 45511 | HN27: 45512 | HO27: 45513 | HP27: 45514 | HQ27: 45515 | HR27: 45516 | HS27: 45517 | HT27: 45518 | HU27: 45519 | HV27: 45520 | HW27: 45521 | HX27: 45522 | HY27: 45523 | HZ27: 45524 | IA27: 45525 | IB27: 45526 | IC27: 45527 | ID27: 45528 | IE27: 45529 | IF27: 45530 | IG27: 45531 | IH27: 45532 | II27: 45533 | IJ27: 45534 | IK27: 45535 | IL27: 45536 | IM27: 45537 | IN27: 45538 | IO27: 45539 | IP27: 45540 | IQ27: 45541 | IR27: 45542 | IS27: 45543 | IT27: 45544 | IU27: 45545 | IV27: 45546 | IW27: 45547 | IX27: 45548 | IY27: 45549 | IZ27: 45550 | JA27: 45551 | JB27: 45552 | JC27: 45553 | JD27: 45554 | JE27: 45555 | JF27: 45556 | JG27: 45557 | JH27: 45558 | JI27: 45559 | JJ27: 45560 | JK27: 45561 | JL27: 45562 | JM27: 45563 | JN27: 45564 | JO27: 45565 | JP27: 45566 | JQ27: 45567 | JR27: 45568 | JS27: 45569 | JT27: 45570 | JU27: 45571 | JV27: 45572 | JW27: 45573 | JX27: 45574 | JY27: 45575 | JZ27: 45576 | KA27: 45577 | KB27: 45578 | KC27: 45579 | KD27: 45580 | KE27: 45581 | KF27: 45582 | KG27: 45583 | KH27: 45584 | KI27: 45585 | KJ27: 45586 | KK27: 45587 | KL27: 45588 | KM27: 45589 | KN27: 45590 | KO27: 45591 | KP27: 45592 | KQ27: 45593 | KR27: 45594 | KS27: 45595 | KT27: 45596 | KU27: 45597 | KV27: 45598 | KW27: 45599 | KX27: 45600 | KY27: 45601 | KZ27: 45602 | LA27: 45603 | LB27: 45604 | LC27: 45605 | LD27: 45606 | LE27: 45607 | LF27: 45608 | LG27: 45609 | LH27: 45610 | LI27: 45611 | LJ27: 45612 | LK27: 45613 | LL27: 45614 | LM27: 45615 | LN27: 45616 | LO27: 45617 | LP27: 45618 | LQ27: 45619 | LR27: 45620 | LS27: 45621 | LT27: 45622 | LU27: 45623 | LV27: 45624 | LW27: 45625 | LX27: 45626 | LY27: 45627 | LZ27: 45628 | MA27: 45629 | MB27: 45630 | MC27: 45631 | MD27: 45632 | ME27: 45633 | MF27: 45634 | MG27: 45635 | MH27: 45636 | MI27: 45637 | MJ27: 45638 | MK27: 45639 | ML27: 45640 | MM27: 45641 | MN27: 45642 | MO27: 45643 | MP27: 45644 | MQ27: 45645 | MR27: 45646 | MS27: 45647 | MT27: 45648 | MU27: 45649 | MV27: 45650 | MW27: 45651 | MX27: 45652 | MY27: 45653 | MZ27: 45654 | NA27: 45655 | NB27: 45656 | NC27: 45657
A28: Máximo estudiantes simultáneos día | B28: =COUNTIFS('HISTÓRICO 2023-2026'!$M:$M,"<="&B$27,'HISTÓRICO 2023-2026'!$N:$N,">="&B$27) -> 8 | C28: =COUNTIFS('HISTÓRICO 2023-2026'!$M:$M,"<="&C$27,'HISTÓRICO 2023-2026'!$N:$N,">="&C$27) -> 8 | D28: =COUNTIFS('HISTÓRICO 2023-2026'!$M:$M,"<="&D$27,'HISTÓRICO 2023-2026'!$N:$N,">="&D$27) -> 8 | E28: =COUNTIFS('HISTÓRICO 2023-2026'!$M:$M,"<="&E$27,'HISTÓRICO 2023-2026'!$N:$N,">="&E$27) -> 8 | F28: =COUNTIFS('HISTÓRICO 2023-2026'!$M:$M,"<="&F$27,'HISTÓRICO 2023-2026'!$N:$N,">="&F$27) -> 8 | G28: =COUNTIFS('HISTÓRICO 2023-2026'!$M:$M,"<="&G$27,'HISTÓRICO 2023-2026'!$N:$N,">="&G$27) -> 8 | H28: =COUNTIFS('HISTÓRICO 2023-2026'!$M:$M,"<="&H$27,'HISTÓRICO 2023-2026'!$N:$N,">="&H$27) -> 7 | I28: =COUNTIFS('HISTÓRICO 2023-2026'!$M:$M,"<="&I$27,'HISTÓRICO 2023-2026'!$N:$N,">="&I$27) -> 7 | ... NC28: =COUNTIFS('HISTÓRICO 2023-2026'!$M:$M,"<="&NC$27,'HISTÓRICO 2023-2026'!$N:$N,">="&NC$27) -> 24
A29: Máximo estudiantes simultáneos mes | B29: =MAX(B28:AF28) -> 8 | AG29: =MAX(AG28:BI28) -> 2 | BJ29: =MAX(BJ28:CN28) -> 89 | CO29: =MAX(CO28:DR28) -> 245 | DS29: =MAX(DS28:EW28) -> 394 | EX29: =MAX(EX28:GA28) -> 343 | GB29: =MAX(GB28:HF28) -> 248 | HG29: =MAX(HG28:IK28) -> 285 | IL29: =MAX(IL28:JO28) -> 315 | JP29: =MAX(JP28:KT28) -> 465 | KU29: =MAX(KU28:LX28) -> 441 | LY29: =MAX(LY28:NC28) -> 339
A30: Mínimo estudiantes simultáneos mes | B30: {=MIN(IF(B28:AF28>0, B28:AF28))} -> 2 | AG30: {=MIN(IF(AG28:BI28>0, AG28:BI28))} -> 2 | BJ30: {=MIN(IF(BJ28:CN28>0, BJ28:CN28))} -> 2 | CO30: {=MIN(IF(CO28:DR28>0, CO28:DR28))} -> 115 | DS30: {=MIN(IF(DS28:EW28>0, DS28:EW28))} -> 233 | EX30: {=MIN(IF(EX28:GA28>0, EX28:GA28))} -> 245 | GB30: {=MIN(IF(GB28:HF28>0, GB28:HF28))} -> 75 | HG30: {=MIN(IF(HG28:IK28>0, HG28:IK28))} -> 65 | IL30: {=MIN(IF(IL28:JO28>0, IL28:JO28))} -> 229 | JP30: {=MIN(IF(JP28:KT28>0, JP28:KT28))} -> 227 | KU30: {=MIN(IF(KU28:LX28>0, KU28:LX28))} -> 221 | LY30: {=MIN(IF(LY28:NC28>0, LY28:NC28))} -> 24
A32: AÑO 2025 | B32: ENERO | AG32: FEBRERO | BI32: MARZO | CN32: ABRIL | DR32: MAYO | EW32: JUNIO | GA32: JULIO | HF32: AGOSTO | IK32: SEPTIEMBRE | JO32: OCTUBRE | KT32: NOVIEMBRE | LX32: DICIEMBRE
B33: Miércoles | C33: Jueves | D33: Viernes | E33: Sábado | F33: Domingo | G33: Lunes | H33: Martes | I33: Miércoles | J33: Jueves | K33: Viernes | L33: Sábado | M33: Domingo | N33: Lunes | O33: Martes | P33: Miércoles | Q33: Jueves | R33: Viernes | S33: Sábado | T33: Domingo | U33: Lunes | V33: Martes | W33: Miércoles | X33: Jueves | Y33: Viernes | Z33: Sábado | AA33: Domingo | AB33: Lunes | AC33: Martes | AD33: Miércoles | AE33: Jueves | AF33: Viernes | AG33: Sábado | AH33: Domingo | AI33: Lunes | AJ33: Martes | AK33: Miércoles | AL33: Jueves | AM33: Viernes | AN33: Sábado | AO33: Domingo | AP33: Lunes | AQ33: Martes | AR33: Miércoles | AS33: Jueves | AT33: Viernes | AU33: Sábado | AV33: Domingo | AW33: Lunes | AX33: Martes | AY33: Miércoles | AZ33: Jueves | BA33: Viernes | BB33: Sábado | BC33: Domingo | BD33: Lunes | BE33: Martes | BF33: Miércoles | BG33: Jueves | BH33: Viernes | BI33: Sábado | BJ33: Domingo | BK33: Lunes | BL33: Martes | BM33: Miércoles | BN33: Jueves | BO33: Viernes | BP33: Sábado | BQ33: Domingo | BR33: Lunes | BS33: Martes | BT33: Miércoles | BU33: Jueves | BV33: Viernes | BW33: Sábado | BX33: Domingo | BY33: Lunes | BZ33: Martes | CA33: Miércoles | CB33: Jueves | CC33: Viernes | CD33: Sábado | CE33: Domingo | CF33: Lunes | CG33: Martes | CH33: Miércoles | CI33: Jueves | CJ33: Viernes | CK33: Sábado | CL33: Domingo | CM33: Lunes | CN33: Martes | CO33: Miércoles | CP33: Jueves | CQ33: Viernes | CR33: Sábado | CS33: Domingo | CT33: Lunes | CU33: Martes | CV33: Miércoles | CW33: Jueves | CX33: Viernes | CY33: Sábado | CZ33: Domingo | DA33: Lunes | DB33: Martes | DC33: Miércoles | DD33: Jueves | DE33: Viernes | DF33: Sábado | DG33: Domingo | DH33: Lunes | DI33: Martes | DJ33: Miércoles | DK33: Jueves | DL33: Viernes | DM33: Sábado | DN33: Domingo | DO33: Lunes | DP33: Martes | DQ33: Miércoles | DR33: Jueves | DS33: Viernes | DT33: Sábado | DU33: Domingo | DV33: Lunes | DW33: Martes | DX33: Miércoles | DY33: Jueves | DZ33: Viernes | EA33: Sábado | EB33: Domingo | EC33: Lunes | ED33: Martes | EE33: Miércoles | EF33: Jueves | EG33: Viernes | EH33: Sábado | EI33: Domingo | EJ33: Lunes | EK33: Martes | EL33: Miércoles | EM33: Jueves | EN33: Viernes | EO33: Sábado | EP33: Domingo | EQ33: Lunes | ER33: Martes | ES33: Miércoles | ET33: Jueves | EU33: Viernes | EV33: Sábado | EW33: Domingo | EX33: Lunes | EY33: Martes | EZ33: Miércoles | FA33: Jueves | FB33: Viernes | FC33: Sábado | FD33: Domingo | FE33: Lunes | FF33: Martes | FG33: Miércoles | FH33: Jueves | FI33: Viernes | FJ33: Sábado | FK33: Domingo | FL33: Lunes | FM33: Martes | FN33: Miércoles | FO33: Jueves | FP33: Viernes | FQ33: Sábado | FR33: Domingo | FS33: Lunes | FT33: Martes | FU33: Miércoles | FV33: Jueves | FW33: Viernes | FX33: Sábado | FY33: Domingo | FZ33: Lunes | GA33: Martes | GB33: Miércoles | GC33: Jueves | GD33: Viernes | GE33: Sábado | GF33: Domingo | GG33: Lunes | GH33: Martes | GI33: Miércoles | GJ33: Jueves | GK33: Viernes | GL33: Sábado | GM33: Domingo | GN33: Lunes | GO33: Martes | GP33: Miércoles | GQ33: Jueves | GR33: Viernes | GS33: Sábado | GT33: Domingo | GU33: Lunes | GV33: Martes | GW33: Miércoles | GX33: Jueves | GY33: Viernes | GZ33: Sábado | HA33: Domingo | HB33: Lunes | HC33: Martes | HD33: Miércoles | HE33: Jueves | HF33: Viernes | HG33: Sábado | HH33: Domingo | HI33: Lunes | HJ33: Martes | HK33: Miércoles | HL33: Jueves | HM33: Viernes | HN33: Sábado | HO33: Domingo | HP33: Lunes | HQ33: Martes | HR33: Miércoles | HS33: Jueves | HT33: Viernes | HU33: Sábado | HV33: Domingo | HW33: Lunes | HX33: Martes | HY33: Miércoles | HZ33: Jueves | IA33: Viernes | IB33: Sábado | IC33: Domingo | ID33: Lunes | IE33: Martes | IF33: Miércoles | IG33: Jueves | IH33: Viernes | II33: Sábado | IJ33: Domingo | IK33: Lunes | IL33: Martes | IM33: Miércoles | IN33: Jueves | IO33: Viernes | IP33: Sábado | IQ33: Domingo | IR33: Lunes | IS33: Martes | IT33: Miércoles | IU33: Jueves | IV33: Viernes | IW33: Sábado | IX33: Domingo | IY33: Lunes | IZ33: Martes | JA33: Miércoles | JB33: Jueves | JC33: Viernes | JD33: Sábado | JE33: Domingo | JF33: Lunes | JG33: Martes | JH33: Miércoles | JI33: Jueves | JJ33: Viernes | JK33: Sábado | JL33: Domingo | JM33: Lunes | JN33: Martes | JO33: Miércoles | JP33: Jueves | JQ33: Viernes | JR33: Sábado | JS33: Domingo | JT33: Lunes | JU33: Martes | JV33: Miércoles | JW33: Jueves | JX33: Viernes | JY33: Sábado | JZ33: Domingo | KA33: Lunes | KB33: Martes | KC33: Miércoles | KD33: Jueves | KE33: Viernes | KF33: Sábado | KG33: Domingo | KH33: Lunes | KI33: Martes | KJ33: Miércoles | KK33: Jueves | KL33: Viernes | KM33: Sábado | KN33: Domingo | KO33: Lunes | KP33: Martes | KQ33: Miércoles | KR33: Jueves | KS33: Viernes | KT33: Sábado | KU33: Domingo | KV33: Lunes | KW33: Martes | KX33: Miércoles | KY33: Jueves | KZ33: Viernes | LA33: Sábado | LB33: Domingo | LC33: Lunes | LD33: Martes | LE33: Miércoles | LF33: Jueves | LG33: Viernes | LH33: Sábado | LI33: Domingo | LJ33: Lunes | LK33: Martes | LL33: Miércoles | LM33: Jueves | LN33: Viernes | LO33: Sábado | LP33: Domingo | LQ33: Lunes | LR33: Martes | LS33: Miércoles | LT33: Jueves | LU33: Viernes | LV33: Sábado | LW33: Domingo | LX33: Lunes | LY33: Martes | LZ33: Miércoles | MA33: Jueves | MB33: Viernes | MC33: Sábado | MD33: Domingo | ME33: Lunes | MF33: Martes | MG33: Miércoles | MH33: Jueves | MI33: Viernes | MJ33: Sábado | MK33: Domingo | ML33: Lunes | MM33: Martes | MN33: Miércoles | MO33: Jueves | MP33: Viernes | MQ33: Sábado | MR33: Domingo | MS33: Lunes | MT33: Martes | MU33: Miércoles | MV33: Jueves | MW33: Viernes | MX33: Sábado | MY33: Domingo | MZ33: Lunes | NA33: Martes | NB33: Miércoles
B34: 45658 | C34: 45659 | D34: 45660 | E34: 45661 | F34: 45662 | G34: 45663 | H34: 45664 | I34: 45665 | J34: 45666 | K34: 45667 | L34: 45668 | M34: 45669 | N34: 45670 | O34: 45671 | P34: 45672 | Q34: 45673 | R34: 45674 | S34: 45675 | T34: 45676 | U34: 45677 | V34: 45678 | W34: 45679 | X34: 45680 | Y34: 45681 | Z34: 45682 | AA34: 45683 | AB34: 45684 | AC34: 45685 | AD34: 45686 | AE34: 45687 | AF34: 45688 | AG34: 45689 | AH34: 45690 | AI34: 45691 | AJ34: 45692 | AK34: 45693 | AL34: 45694 | AM34: 45695 | AN34: 45696 | AO34: 45697 | AP34: 45698 | AQ34: 45699 | AR34: 45700 | AS34: 45701 | AT34: 45702 | AU34: 45703 | AV34: 45704 | AW34: 45705 | AX34: 45706 | AY34: 45707 | AZ34: 45708 | BA34: 45709 | BB34: 45710 | BC34: 45711 | BD34: 45712 | BE34: 45713 | BF34: 45714 | BG34: 45715 | BH34: 45716 | BI34: 45717 | BJ34: 45718 | BK34: 45719 | BL34: 45720 | BM34: 45721 | BN34: 45722 | BO34: 45723 | BP34: 45724 | BQ34: 45725 | BR34: 45726 | BS34: 45727 | BT34: 45728 | BU34: 45729 | BV34: 45730 | BW34: 45731 | BX34: 45732 | BY34: 45733 | BZ34: 45734 | CA34: 45735 | CB34: 45736 | CC34: 45737 | CD34: 45738 | CE34: 45739 | CF34: 45740 | CG34: 45741 | CH34: 45742 | CI34: 45743 | CJ34: 45744 | CK34: 45745 | CL34: 45746 | CM34: 45747 | CN34: 45748 | CO34: 45749 | CP34: 45750 | CQ34: 45751 | CR34: 45752 | CS34: 45753 | CT34: 45754 | CU34: 45755 | CV34: 45756 | CW34: 45757 | CX34: 45758 | CY34: 45759 | CZ34: 45760 | DA34: 45761 | DB34: 45762 | DC34: 45763 | DD34: 45764 | DE34: 45765 | DF34: 45766 | DG34: 45767 | DH34: 45768 | DI34: 45769 | DJ34: 45770 | DK34: 45771 | DL34: 45772 | DM34: 45773 | DN34: 45774 | DO34: 45775 | DP34: 45776 | DQ34: 45777 | DR34: 45778 | DS34: 45779 | DT34: 45780 | DU34: 45781 | DV34: 45782 | DW34: 45783 | DX34: 45784 | DY34: 45785 | DZ34: 45786 | EA34: 45787 | EB34: 45788 | EC34: 45789 | ED34: 45790 | EE34: 45791 | EF34: 45792 | EG34: 45793 | EH34: 45794 | EI34: 45795 | EJ34: 45796 | EK34: 45797 | EL34: 45798 | EM34: 45799 | EN34: 45800 | EO34: 45801 | EP34: 45802 | EQ34: 45803 | ER34: 45804 | ES34: 45805 | ET34: 45806 | EU34: 45807 | EV34: 45808 | EW34: 45809 | EX34: 45810 | EY34: 45811 | EZ34: 45812 | FA34: 45813 | FB34: 45814 | FC34: 45815 | FD34: 45816 | FE34: 45817 | FF34: 45818 | FG34: 45819 | FH34: 45820 | FI34: 45821 | FJ34: 45822 | FK34: 45823 | FL34: 45824 | FM34: 45825 | FN34: 45826 | FO34: 45827 | FP34: 45828 | FQ34: 45829 | FR34: 45830 | FS34: 45831 | FT34: 45832 | FU34: 45833 | FV34: 45834 | FW34: 45835 | FX34: 45836 | FY34: 45837 | FZ34: 45838 | GA34: 45839 | GB34: 45840 | GC34: 45841 | GD34: 45842 | GE34: 45843 | GF34: 45844 | GG34: 45845 | GH34: 45846 | GI34: 45847 | GJ34: 45848 | GK34: 45849 | GL34: 45850 | GM34: 45851 | GN34: 45852 | GO34: 45853 | GP34: 45854 | GQ34: 45855 | GR34: 45856 | GS34: 45857 | GT34: 45858 | GU34: 45859 | GV34: 45860 | GW34: 45861 | GX34: 45862 | GY34: 45863 | GZ34: 45864 | HA34: 45865 | HB34: 45866 | HC34: 45867 | HD34: 45868 | HE34: 45869 | HF34: 45870 | HG34: 45871 | HH34: 45872 | HI34: 45873 | HJ34: 45874 | HK34: 45875 | HL34: 45876 | HM34: 45877 | HN34: 45878 | HO34: 45879 | HP34: 45880 | HQ34: 45881 | HR34: 45882 | HS34: 45883 | HT34: 45884 | HU34: 45885 | HV34: 45886 | HW34: 45887 | HX34: 45888 | HY34: 45889 | HZ34: 45890 | IA34: 45891 | IB34: 45892 | IC34: 45893 | ID34: 45894 | IE34: 45895 | IF34: 45896 | IG34: 45897 | IH34: 45898 | II34: 45899 | IJ34: 45900 | IK34: 45901 | IL34: 45902 | IM34: 45903 | IN34: 45904 | IO34: 45905 | IP34: 45906 | IQ34: 45907 | IR34: 45908 | IS34: 45909 | IT34: 45910 | IU34: 45911 | IV34: 45912 | IW34: 45913 | IX34: 45914 | IY34: 45915 | IZ34: 45916 | JA34: 45917 | JB34: 45918 | JC34: 45919 | JD34: 45920 | JE34: 45921 | JF34: 45922 | JG34: 45923 | JH34: 45924 | JI34: 45925 | JJ34: 45926 | JK34: 45927 | JL34: 45928 | JM34: 45929 | JN34: 45930 | JO34: 45931 | JP34: 45932 | JQ34: 45933 | JR34: 45934 | JS34: 45935 | JT34: 45936 | JU34: 45937 | JV34: 45938 | JW34: 45939 | JX34: 45940 | JY34: 45941 | JZ34: 45942 | KA34: 45943 | KB34: 45944 | KC34: 45945 | KD34: 45946 | KE34: 45947 | KF34: 45948 | KG34: 45949 | KH34: 45950 | KI34: 45951 | KJ34: 45952 | KK34: 45953 | KL34: 45954 | KM34: 45955 | KN34: 45956 | KO34: 45957 | KP34: 45958 | KQ34: 45959 | KR34: 45960 | KS34: 45961 | KT34: 45962 | KU34: 45963 | KV34: 45964 | KW34: 45965 | KX34: 45966 | KY34: 45967 | KZ34: 45968 | LA34: 45969 | LB34: 45970 | LC34: 45971 | LD34: 45972 | LE34: 45973 | LF34: 45974 | LG34: 45975 | LH34: 45976 | LI34: 45977 | LJ34: 45978 | LK34: 45979 | LL34: 45980 | LM34: 45981 | LN34: 45982 | LO34: 45983 | LP34: 45984 | LQ34: 45985 | LR34: 45986 | LS34: 45987 | LT34: 45988 | LU34: 45989 | LV34: 45990 | LW34: 45991 | LX34: 45992 | LY34: 45993 | LZ34: 45994 | MA34: 45995 | MB34: 45996 | MC34: 45997 | MD34: 45998 | ME34: 45999 | MF34: 46000 | MG34: 46001 | MH34: 46002 | MI34: 46003 | MJ34: 46004 | MK34: 46005 | ML34: 46006 | MM34: 46007 | MN34: 46008 | MO34: 46009 | MP34: 46010 | MQ34: 46011 | MR34: 46012 | MS34: 46013 | MT34: 46014 | MU34: 46015 | MV34: 46016 | MW34: 46017 | MX34: 46018 | MY34: 46019 | MZ34: 46020 | NA34: 46021 | NB34: 46022
A35: Máximo estudiantes simultáneos día | B35: =COUNTIFS('HISTÓRICO 2023-2026'!$M:$M,"<="&B$34,'HISTÓRICO 2023-2026'!$N:$N,">="&B$34) -> 24 | C35: =COUNTIFS('HISTÓRICO 2023-2026'!$M:$M,"<="&C$34,'HISTÓRICO 2023-2026'!$N:$N,">="&C$34) -> 24 | D35: =COUNTIFS('HISTÓRICO 2023-2026'!$M:$M,"<="&D$34,'HISTÓRICO 2023-2026'!$N:$N,">="&D$34) -> 23 | E35: =COUNTIFS('HISTÓRICO 2023-2026'!$M:$M,"<="&E$34,'HISTÓRICO 2023-2026'!$N:$N,">="&E$34) -> 20 | F35: =COUNTIFS('HISTÓRICO 2023-2026'!$M:$M,"<="&F$34,'HISTÓRICO 2023-2026'!$N:$N,">="&F$34) -> 16 | G35: =COUNTIFS('HISTÓRICO 2023-2026'!$M:$M,"<="&G$34,'HISTÓRICO 2023-2026'!$N:$N,">="&G$34) -> 77 | H35: =COUNTIFS('HISTÓRICO 2023-2026'!$M:$M,"<="&H$34,'HISTÓRICO 2023-2026'!$N:$N,">="&H$34) -> 77 | I35: =COUNTIFS('HISTÓRICO 2023-2026'!$M:$M,"<="&I$34,'HISTÓRICO 2023-2026'!$N:$N,">="&I$34) -> 77 | ... NB35: =COUNTIFS('HISTÓRICO 2023-2026'!$M:$M,"<="&NB$34,'HISTÓRICO 2023-2026'!$N:$N,">="&NB$34) -> 48
A36: Máximo estudiantes simultáneos mes | B36: =MAX(B35:AF35) -> 79 | AG36: =MAX(AG35:BH35) -> 120 | BI36: =MAX(BI35:CM35) -> 391 | CN36: =MAX(CN35:DQ35) -> 426 | DR36: =MAX(DR35:EV35) -> 527 | EW36: =MAX(EW35:FZ35) -> 489 | GA36: =MAX(GA35:HE35) -> 267 | HF36: =MAX(HF35:IJ35) -> 351 | IK36: =MAX(IK35:JN35) -> 421 | JO36: =MAX(JO35:KS35) -> 488 | KT36: =MAX(KT35:LW35) -> 404 | LX36: =MAX(LX35:NB35) -> 277
A37: Mínimo estudiantes simultáneos mes | B37: {=MIN(IF(B35:AF35>0, B35:AF35))} -> 16 | AG37: {=MIN(IF(AG35:BH35>0, AG35:BH35))} -> 68 | BI37: {=MIN(IF(BI35:CM35>0, BI35:CM35))} -> 121 | CN37: {=MIN(IF(CN35:DQ35>0, CN35:DQ35))} -> 335 | DR37: {=MIN(IF(DR35:EV35>0, DR35:EV35))} -> 402 | EW37: {=MIN(IF(EW35:FZ35>0, EW35:FZ35))} -> 252 | GA37: {=MIN(IF(GA35:HE35>0, GA35:HE35))} -> 121 | HF37: {=MIN(IF(HF35:IJ35>0, HF35:IJ35))} -> 121 | IK37: {=MIN(IF(IK35:JN35>0, IK35:JN35))} -> 236 | JO37: {=MIN(IF(JO35:KS35>0, JO35:KS35))} -> 299 | KT37: {=MIN(IF(KT35:LW35>0, KT35:LW35))} -> 209 | LX37: {=MIN(IF(LX35:NB35>0, LX35:NB35))} -> 35
A39: AÑO 2026 | B39: ENERO | AG39: FEBRERO | BI39: MARZO | CN39: ABRIL | DR39: MAYO | EW39: JUNIO | GA39: JULIO | HF39: AGOSTO | IK39: SEPTIEMBRE | JO39: OCTUBRE | KT39: NOVIEMBRE | LX39: DICIEMBRE
B40: Jueves | C40: Viernes | D40: Sábado | E40: Domingo | F40: Lunes | G40: Martes | H40: Miércoles | I40: Jueves | J40: Viernes | K40: Sábado | L40: Domingo | M40: Lunes | N40: Martes | O40: Miércoles | P40: Jueves | Q40: Viernes | R40: Sábado | S40: Domingo | T40: Lunes | U40: Martes | V40: Miércoles | W40: Jueves | X40: Viernes | Y40: Sábado | Z40: Domingo | AA40: Lunes | AB40: Martes | AC40: Miércoles | AD40: Jueves | AE40: Viernes | AF40: Sábado | AG40: Domingo | AH40: Lunes | AI40: Martes | AJ40: Miércoles | AK40: Jueves | AL40: Viernes | AM40: Sábado | AN40: Domingo | AO40: Lunes | AP40: Martes | AQ40: Miércoles | AR40: Jueves | AS40: Viernes | AT40: Sábado | AU40: Domingo | AV40: Lunes | AW40: Martes | AX40: Miércoles | AY40: Jueves | AZ40: Viernes | BA40: Sábado | BB40: Domingo | BC40: Lunes | BD40: Martes | BE40: Miércoles | BF40: Jueves | BG40: Viernes | BH40: Sábado | BI40: Domingo | BJ40: Lunes | BK40: Martes | BL40: Miércoles | BM40: Jueves | BN40: Viernes | BO40: Sábado | BP40: Domingo | BQ40: Lunes | BR40: Martes | BS40: Miércoles | BT40: Jueves | BU40: Viernes | BV40: Sábado | BW40: Domingo | BX40: Lunes | BY40: Martes | BZ40: Miércoles | CA40: Jueves | CB40: Viernes | CC40: Sábado | CD40: Domingo | CE40: Lunes | CF40: Martes | CG40: Miércoles | CH40: Jueves | CI40: Viernes | CJ40: Sábado | CK40: Domingo | CL40: Lunes | CM40: Martes | CN40: Miércoles | CO40: Jueves | CP40: Viernes | CQ40: Sábado | CR40: Domingo | CS40: Lunes | CT40: Martes | CU40: Miércoles | CV40: Jueves | CW40: Viernes | CX40: Sábado | CY40: Domingo | CZ40: Lunes | DA40: Martes | DB40: Miércoles | DC40: Jueves | DD40: Viernes | DE40: Sábado | DF40: Domingo | DG40: Lunes | DH40: Martes | DI40: Miércoles | DJ40: Jueves | DK40: Viernes | DL40: Sábado | DM40: Domingo | DN40: Lunes | DO40: Martes | DP40: Miércoles | DQ40: Jueves | DR40: Viernes | DS40: Sábado | DT40: Domingo | DU40: Lunes | DV40: Martes | DW40: Miércoles | DX40: Jueves | DY40: Viernes | DZ40: Sábado | EA40: Domingo | EB40: Lunes | EC40: Martes | ED40: Miércoles | EE40: Jueves | EF40: Viernes | EG40: Sábado | EH40: Domingo | EI40: Lunes | EJ40: Martes | EK40: Miércoles | EL40: Jueves | EM40: Viernes | EN40: Sábado | EO40: Domingo | EP40: Lunes | EQ40: Martes | ER40: Miércoles | ES40: Jueves | ET40: Viernes | EU40: Sábado | EV40: Domingo | EW40: Lunes | EX40: Martes | EY40: Miércoles | EZ40: Jueves | FA40: Viernes | FB40: Sábado | FC40: Domingo | FD40: Lunes | FE40: Martes | FF40: Miércoles | FG40: Jueves | FH40: Viernes | FI40: Sábado | FJ40: Domingo | FK40: Lunes | FL40: Martes | FM40: Miércoles | FN40: Jueves | FO40: Viernes | FP40: Sábado | FQ40: Domingo | FR40: Lunes | FS40: Martes | FT40: Miércoles | FU40: Jueves | FV40: Viernes | FW40: Sábado | FX40: Domingo | FY40: Lunes | FZ40: Martes | GA40: Miércoles | GB40: Jueves | GC40: Viernes | GD40: Sábado | GE40: Domingo | GF40: Lunes | GG40: Martes | GH40: Miércoles | GI40: Jueves | GJ40: Viernes | GK40: Sábado | GL40: Domingo | GM40: Lunes | GN40: Martes | GO40: Miércoles | GP40: Jueves | GQ40: Viernes | GR40: Sábado | GS40: Domingo | GT40: Lunes | GU40: Martes | GV40: Miércoles | GW40: Jueves | GX40: Viernes | GY40: Sábado | GZ40: Domingo | HA40: Lunes | HB40: Martes | HC40: Miércoles | HD40: Jueves | HE40: Viernes | HF40: Sábado | HG40: Domingo | HH40: Lunes | HI40: Martes | HJ40: Miércoles | HK40: Jueves | HL40: Viernes | HM40: Sábado | HN40: Domingo | HO40: Lunes | HP40: Martes | HQ40: Miércoles | HR40: Jueves | HS40: Viernes | HT40: Sábado | HU40: Domingo | HV40: Lunes | HW40: Martes | HX40: Miércoles | HY40: Jueves | HZ40: Viernes | IA40: Sábado | IB40: Domingo | IC40: Lunes | ID40: Martes | IE40: Miércoles | IF40: Jueves | IG40: Viernes | IH40: Sábado | II40: Domingo | IJ40: Lunes | IK40: Martes | IL40: Miércoles | IM40: Jueves | IN40: Viernes | IO40: Sábado | IP40: Domingo | IQ40: Lunes | IR40: Martes | IS40: Miércoles | IT40: Jueves | IU40: Viernes | IV40: Sábado | IW40: Domingo | IX40: Lunes | IY40: Martes | IZ40: Miércoles | JA40: Jueves | JB40: Viernes | JC40: Sábado | JD40: Domingo | JE40: Lunes | JF40: Martes | JG40: Miércoles | JH40: Jueves | JI40: Viernes | JJ40: Sábado | JK40: Domingo | JL40: Lunes | JM40: Martes | JN40: Miércoles | JO40: Jueves | JP40: Viernes | JQ40: Sábado | JR40: Domingo | JS40: Lunes | JT40: Martes | JU40: Miércoles | JV40: Jueves | JW40: Viernes | JX40: Sábado | JY40: Domingo | JZ40: Lunes | KA40: Martes | KB40: Miércoles | KC40: Jueves | KD40: Viernes | KE40: Sábado | KF40: Domingo | KG40: Lunes | KH40: Martes | KI40: Miércoles | KJ40: Jueves | KK40: Viernes | KL40: Sábado | KM40: Domingo | KN40: Lunes | KO40: Martes | KP40: Miércoles | KQ40: Jueves | KR40: Viernes | KS40: Sábado | KT40: Domingo | KU40: Lunes | KV40: Martes | KW40: Miércoles | KX40: Jueves | KY40: Viernes | KZ40: Sábado | LA40: Domingo | LB40: Lunes | LC40: Martes | LD40: Miércoles | LE40: Jueves | LF40: Viernes | LG40: Sábado | LH40: Domingo | LI40: Lunes | LJ40: Martes | LK40: Miércoles | LL40: Jueves | LM40: Viernes | LN40: Sábado | LO40: Domingo | LP40: Lunes | LQ40: Martes | LR40: Miércoles | LS40: Jueves | LT40: Viernes | LU40: Sábado | LV40: Domingo | LW40: Lunes | LX40: Martes | LY40: Miércoles | LZ40: Jueves | MA40: Viernes | MB40: Sábado | MC40: Domingo | MD40: Lunes | ME40: Martes | MF40: Miércoles | MG40: Jueves | MH40: Viernes | MI40: Sábado | MJ40: Domingo | MK40: Lunes | ML40: Martes | MM40: Miércoles | MN40: Jueves | MO40: Viernes | MP40: Sábado | MQ40: Domingo | MR40: Lunes | MS40: Martes | MT40: Miércoles | MU40: Jueves | MV40: Viernes | MW40: Sábado | MX40: Domingo | MY40: Lunes | MZ40: Martes | NA40: Miércoles | NB40: Jueves
